Workbook

Sheet LFB1
A1: Supplier | B1: NAME | C1: Company Code | D1: Trading partner | E1: Created On | F1: Created by | G1: Payment Block | H1: Terms of Payment | I1: Check Double Invoice
A2: 1000 | B2: =VLOOKUP(A2,'LFA1'!A:C,3,FALSE) -> CYBEX GmbH | C2: CZ02 | D2: =VLOOKUP(A2,'LFA1'!A:J,10,0) -> CBGM | E2: 43136 | F2: HEMPELJU | H2: Z106
A3: 1000 | B3: =VLOOKUP(A3,'LFA1'!A:C,3,FALSE) -> CYBEX GmbH | C3: US02 | D3: =VLOOKUP(A3,'LFA1'!A:J,10,0) -> CBGM | E3: 44403 | F3: SCHULZEST | H3: Z104
A4: 1003 | B4: =VLOOKUP(A4,'LFA1'!A:C,3,FALSE) -> Columbus Trading Partners | C4: CH02 | D4: =VLOOKUP(A4,'LFA1'!A:J,10,0) -> CTPE | E4: 43923 | F4: VIDDAD01 | H4: 0001
A5: 1003 | B5: =VLOOKUP(A5,'LFA1'!A:C,3,FALSE) -> Columbus Trading Partners | C5: GB02 | D5: =VLOOKUP(A5,'LFA1'!A:J,10,0) -> CTPE | E5: 44195 | F5: YUSMOH01
A6: 1003 | B6: =VLOOKUP(A6,'LFA1'!A:C,3,FALSE) -> Columbus Trading Partners | C6: NO02 | D6: =VLOOKUP(A6,'LFA1'!A:J,10,0) -> CTPE | E6: 44095 | F6: YUSMOH01 | H6: 0001
A7: 1009 | B7: =VLOOKUP(A7,'LFA1'!A:C,3,FALSE) -> GB GmbH | C7: US02 | D7: =VLOOKUP(A7,'LFA1'!A:J,10,0) -> GBGM | E7: 44420 | F7: GB_FFUS_MM01 | H7: Z104
A8: 1014 | B8: =VLOOKUP(A8,'LFA1'!A:C,3,FALSE) -> Goodbaby (Hong Kong) Limited | C8: CZ01 | D8: =VLOOKUP(A8,'LFA1'!A:J,10,0) -> GBHK | E8: 43167 | F8: HEMPELJU
A9: 1014 | B9: =VLOOKUP(A9,'LFA1'!A:C,3,FALSE) -> Goodbaby (Hong Kong) Limited | C9: DE08 | D9: =VLOOKUP(A9,'LFA1'!A:J,10,0) -> GBHK | E9: 43406 | F9: HEMPELJU
A10: 1015 | B10: =VLOOKUP(A10,'LFA1'!A:C,3,FALSE) -> Columbus Trading - Partners | C10: CA02 | D10: =VLOOKUP(A10,'LFA1'!A:J,10,0) -> CBUS | E10: 44784 | F10: GURWAD01
A11: 1015 | B11: =VLOOKUP(A11,'LFA1'!A:C,3,FALSE) -> Columbus Trading - Partners | C11: FR70 | D11: =VLOOKUP(A11,'LFA1'!A:J,10,0) -> CBUS | E11: 45777 | F11: FF_EX_SC_BU
A12: 1015 | B12: =VLOOKUP(A12,'LFA1'!A:C,3,FALSE) -> Columbus Trading - Partners | C12: US70 | D12: =VLOOKUP(A12,'LFA1'!A:J,10,0) -> CBUS | E12: 45779 | F12: FF_EX_SC_BU
A13: 1018 | B13: =VLOOKUP(A13,'LFA1'!A:C,3,FALSE) -> Evenflo Company,Inc. | C13: CA02 | D13: =VLOOKUP(A13,'LFA1'!A:J,10,0) -> EFCD | E13: 44903 | F13: BIACIM01
A14: 1018 | B14: =VLOOKUP(A14,'LFA1'!A:C,3,FALSE) -> Evenflo Company,Inc. | C14: CZ02 | D14: =VLOOKUP(A14,'LFA1'!A:J,10,0) -> EFCD | E14: 43978 | F14: NIKBRI01
A15: 1024 | B15: =VLOOKUP(A15,'LFA1'!A:C,3,FALSE) -> Eqo Testing and Certification Co. L | C15: DE02 | D15: =VLOOKUP(A15,'LFA1'!A:J,10,0) -> EQTC | E15: 44678 | F15: SCHULZEST | H15: Z104
A16: 1028 | B16: =VLOOKUP(A16,'LFA1'!A:C,3,FALSE) -> Goodbaby (China) | C16: DE02 | D16: =VLOOKUP(A16,'LFA1'!A:J,10,0) -> GRCN | E16: 43073 | F16: HORNDO
A17: 1030 | B17: =VLOOKUP(A17,'LFA1'!A:C,3,FALSE) -> Columbus Trading-Partners Japan Lim | C17: DE01 | D17: =VLOOKUP(A17,'LFA1'!A:J,10,0) -> CBJP | E17: 43137 | F17: HORNDO | H17: Z107
A18: 1030 | B18: =VLOOKUP(A18,'LFA1'!A:C,3,FALSE) -> Columbus Trading-Partners Japan Lim | C18: DE02 | D18: =VLOOKUP(A18,'LFA1'!A:J,10,0) -> CBJP | E18: 43467 | F18: SABBRE01 | H18: Z107
A19: 1030 | B19: =VLOOKUP(A19,'LFA1'!A:C,3,FALSE) -> Columbus Trading-Partners Japan Lim | C19: DE08 | D19: =VLOOKUP(A19,'LFA1'!A:J,10,0) -> CBJP | E19: 43467 | F19: SABBRE01 | H19: Z107
A20: 1030 | B20: =VLOOKUP(A20,'LFA1'!A:C,3,FALSE) -> Columbus Trading-Partners Japan Lim | C20: DE09 | D20: =VLOOKUP(A20,'LFA1'!A:J,10,0) -> CBJP | E20: 44139 | F20: THICAV01 | H20: Z107
A21: 1031 | B21: =VLOOKUP(A21,'LFA1'!A:C,3,FALSE) -> Rollplay GmbH | C21: DE03 | D21: =VLOOKUP(A21,'LFA1'!A:J,10,0) -> RPGM | E21: 43248 | F21: SIMONAL
A22: 1037 | B22: =VLOOKUP(A22,'LFA1'!A:C,3,FALSE) -> Columbus Trading Partners | C22: US02 | D22: =VLOOKUP(A22,'LFA1'!A:J,10,0) | E22: 44407 | F22: GB_FFUS_MM02
A23: 1038 | B23: =VLOOKUP(A23,'LFA1'!A:C,3,FALSE) -> Piqua | C23: US02 | D23: =VLOOKUP(A23,'LFA1'!A:J,10,0) | E23: 44618 | F23: US_FFID_MM01
A24: 1040 | B24: =VLOOKUP(A24,'LFA1'!A:C,3,FALSE) -> Columbus Trading Partners Gmbh & Co | C24: DE02 | D24: =VLOOKUP(A24,'LFA1'!A:J,10,0) -> CTPE | E24: 43245 | F24: BUIQU
A25: 1040 | B25: =VLOOKUP(A25,'LFA1'!A:C,3,FALSE) -> Columbus Trading Partners Gmbh & Co | C25: DE08 | D25: =VLOOKUP(A25,'LFA1'!A:J,10,0) -> CTPE | E25: 46113 | F25: DENWAS01
A26: 1060 | B26: =VLOOKUP(A26,'LFA1'!A:C,3,FALSE) -> 1060 - FIEGE (Cybex) | C26: DE02 | D26: =VLOOKUP(A26,'LFA1'!A:J,10,0) | E26: 44263 | F26: LALMOH01 | H26: Z106
A27: 1070 | B27: =VLOOKUP(A27,'LFA1'!A:C,3,FALSE) -> 1070 - FIEGE (GB) | C27: DE02 | D27: =VLOOKUP(A27,'LFA1'!A:J,10,0) | E27: 44263 | F27: LALMOH01 | H27: Z106
A28: 1110 | B28: =VLOOKUP(A28,'LFA1'!A:C,3,FALSE) -> Columbus Trading Partner IMEA (FZE) | C28: AE02 | D28: =VLOOKUP(A28,'LFA1'!A:J,10,0) -> CTPF | E28: 45967 | F28: NUWNAN01
A29: 1110 | B29: =VLOOKUP(A29,'LFA1'!A:C,3,FALSE) -> Columbus Trading Partner IMEA (FZE) | C29: AE04 | D29: =VLOOKUP(A29,'LFA1'!A:J,10,0) -> CTPF | E29: 45908 | F29: FF_EX_FI_BU
A30: 1110 | B30: =VLOOKUP(A30,'LFA1'!A:C,3,FALSE) -> Columbus Trading Partner IMEA (FZE) | C30: AE09 | D30: =VLOOKUP(A30,'LFA1'!A:J,10,0) -> CTPF | E30: 45987 | F30: FF_IN_FI_BU
A31: 1900 | B31: =VLOOKUP(A31,'LFA1'!A:C,3,FALSE) -> Goodbaby Czech Republic s.r.o | C31: CZ01 | D31: =VLOOKUP(A31,'LFA1'!A:J,10,0) | E31: 42664 | F31: RFC_GBP
A32: 2000 | B32: =VLOOKUP(A32,'LFA1'!A:C,3,FALSE) -> CYBEX Retail GmbH | C32: AE02 | D32: =VLOOKUP(A32,'LFA1'!A:J,10,0) -> CBRG | E32: 46017 | F32: SUMELV01
A33: 2000 | B33: =VLOOKUP(A33,'LFA1'!A:C,3,FALSE) -> CYBEX Retail GmbH | C33: AE09 | D33: =VLOOKUP(A33,'LFA1'!A:J,10,0) -> CBRG | E33: 46021 | F33: SUMELV01
A34: 2000 | B34: =VLOOKUP(A34,'LFA1'!A:C,3,FALSE) -> CYBEX Retail GmbH | C34: FR70 | D34: =VLOOKUP(A34,'LFA1'!A:J,10,0) -> CBRG | E34: 45616 | F34: FF_EX_SC_BU | H34: Z059
A35: 2020 | B35: =VLOOKUP(A35,'LFA1'!A:C,3,FALSE) -> CYBEX Retail GmbH | C35: DE09 | D35: =VLOOKUP(A35,'LFA1'!A:J,10,0) -> CBRG | E35: 45125 | F35: GB_FF_INT02
A36: 2030 | B36: =VLOOKUP(A36,'LFA1'!A:C,3,FALSE) -> Cybex Retail Store Paris SAS | C36: FR70 | D36: =VLOOKUP(A36,'LFA1'!A:J,10,0) -> CBRF | E36: 45616 | F36: FF_EX_SC_BU | H36: Z059
A37: 2050 | B37: =VLOOKUP(A37,'LFA1'!A:C,3,FALSE) -> CYBEX Retail Berlin | C37: DE09 | D37: =VLOOKUP(A37,'LFA1'!A:J,10,0) -> CBRG | E37: 45939 | F37: FF_EX_SC_BU
A38: 10000 | B38: =VLOOKUP(A38,'LFA1'!A:C,3,FALSE) -> CYBEX GmbH | C38: AE02 | D38: =VLOOKUP(A38,'LFA1'!A:J,10,0) -> CBGM | E38: 45174 | F38: DENWAS01
A39: 10000 | B39: =VLOOKUP(A39,'LFA1'!A:C,3,FALSE) -> CYBEX GmbH | C39: AE04 | D39: =VLOOKUP(A39,'LFA1'!A:J,10,0) -> CBGM | E39: 46094 | F39: SUMELV01
A40: 10000 | B40: =VLOOKUP(A40,'LFA1'!A:C,3,FALSE) -> CYBEX GmbH | C40: CZ01 | D40: =VLOOKUP(A40,'LFA1'!A:J,10,0) -> CBGM | E40: 42725 | F40: HORNDO
...

Sheet LFA1
A1: Supplier | B1: Country/Region Key | C1: Name | D1: Name 2 | E1: Name 3 | F1: Name 4 | G1: City | H1: District | I1: PO Box | J1: Trading Partner No.
A2: 1000 | B2: DE | C2: CYBEX GmbH | G2: Bayreuth | J2: CBGM
A3: 1003 | B3: DE | C3: Columbus Trading Partners | G3: Bayreuth | J3: CTPE
A4: 1009 | B4: DE | C4: GB GmbH | G4: Bayreuth | J4: GBGM
A5: 1014 | B5: HK | C5: Goodbaby (Hong Kong) Limited | G5: San Po Kong, Kowloon | J5: GBHK
A6: 1015 | B6: US | C6: Columbus Trading - Partners | D6: USA Inc. | G6: Boston | H6: Suffolk | J6: CBUS
A7: 1018 | B7: US | C7: Evenflo Company,Inc. | G7: Miamisburg | J7: EFCD
A8: 1024 | B8: CN | C8: Eqo Testing and Certification Co. L | G8: Kunshan | H8: Lujia Town | J8: EQTC
A9: 1028 | B9: CN | C9: Goodbaby (China) | D9: Retail & Service Company | G9: KUNSHAN CITY | J9: GRCN
A10: 1030 | B10: JP | C10: Columbus Trading-Partners Japan Lim | G10: Tokyo | J10: CBJP
A11: 1031 | B11: DE | C11: Rollplay GmbH | G11: Nürnberg | J11: RPGM
A12: 1037 | B12: CN | C12: Columbus Trading Partners | D12: Plant Cust/Vend for 1020 | G12: Shanghai
A13: 1038 | B13: US | C13: Piqua | D13: Plant Cust/Vend for 1031 | G13: Piqua | H13: Miami
A14: 1040 | B14: DE | C14: Columbus Trading Partners Gmbh & Co | D14: c/o Pfenning Logistics GmbH | G14: Monsheim | J14: CTPE
A15: 1060 | B15: CN | C15: 1060 - FIEGE (Cybex) | D15: Fiege Logistics SIP Co., Ltd. | G15: Shanghai
A16: 1070 | B16: CN | C16: 1070 - FIEGE (GB) | D16: Fiege Logistics SIP Co., Ltd. | G16: Shanghai
A17: 1110 | B17: AE | C17: Columbus Trading Partner IMEA (FZE) | G17: Dubai | J17: CTPF
A18: 1900 | B18: CZ | C18: Goodbaby Czech Republic s.r.o
A19: 2000 | B19: DE | C19: CYBEX Retail GmbH | G19: Bayreuth | J19: CBRG
A20: 2020 | B20: NL | C20: CYBEX Retail GmbH | G20: Amsterdam | J20: CBRG
A21: 2030 | B21: FR | C21: Cybex Retail Store Paris SAS | G21: Paris | J21: CBRF
A22: 2050 | B22: DE | C22: CYBEX Retail Berlin | G22: Berlin | J22: CBRG
A23: 10000 | B23: DE | C23: CYBEX GmbH | G23: Bayreuth | J23: CBGM
A24: 10001 | B24: DE | C24: Columbus Trading-Partners GmbH & Co | G24: Bayreuth | J24: CTPE
A25: 10006 | B25: DE | C25: Goodbaby (Europe) GmbH & Co. KG | G25: Bayreuth | J25: GEGC
A26: 10008 | B26: HK | C26: Cybex Industrial Ltd. | G26: Hong Kong | J26: CBHK
A27: 10011 | B27: DE | C27: Columbus Holding GmbH | G27: Bayreuth | J27: CBCH
A28: 10013 | B28: HK | C28: Goodbaby International Holdings Ltd | G28: Hong Kong | J28: GIHL
A29: 10014 | B29: HK | C29: Goodbaby (Hong Kong) Limited | G29: Kunshan City | J29: GBHK
A30: 10015 | B30: US | C30: Columbus Trading - Partners USA Inc | G30: Kennesaw | J30: CBUS
... A32: 10030 | B32: JP | C32: Columbus Trading-Partners Japan Lim | G32: Tokyo | J32: CBJP
A33: 50000 | B33: DE | C33: Philipp Raum | G33: Bayreuth
A34: 50001 | B34: DE | C34: Dmitrij Brandt | G34: Bayreuth
A35: 50002 | B35: DE | C35: Tobias Salzmann | G35: Bayreuth
A36: 50003 | B36: DE | C36: Christian Aschenbrenner | G36: Bayreuth
A37: 50005 | B37: IT | C37: Francesca San Giorgio | G37: Bayreuth
A38: 50006 | B38: DE | C38: Mark Dostal - Key Account Manager G | G38: Bayreuth
A39: 50007 | B39: DE | C39: Herbert Becker - Verkaufsleiter Fac | G39: Bayreuth
A40: 50009 | B40: DE | C40: André Biedenbacher, AD Norddeutschl | G40: Bayreuth
A41: 50010 | B41: DE | C41: Daniel Harrington | G41: Bayreuth
...
